{
  "comments": [
    {
      "key": {
        "uuid": "1a76adc5_614bef59",
        "filename": "utils/functest_utils.py",
        "patchSetId": 4
      },
      "lineNbr": 229,
      "author": {
        "id": 3405
      },
      "writtenOn": "2016-08-23T08:13:29Z",
      "side": 1,
      "message": "you could also have simply used:\nlog.exception(\"Pushing Result to DB failed\")",
      "revId": "2588e2af6c2b609ab08957268f8163954cd8eae1",
      "serverId": "bbac25d2-bf60-4904-9ba8-a72fc000d6c5",
      "unresolved": false
    }
  ]
}